<?xml version="1.0"?>
<sdf version="1.6">
  <world name="warehouse">
    <physics name="1ms" type="ignored">
      <max_step_size>0.001</max_step_size>
      <real_time_factor>1.0</real_time_factor>
    </physics>

    <plugin filename="gz-sim-physics-system" name="gz::sim::systems::Physics"/>
    <plugin filename="gz-sim-user-commands-system" name="gz::sim::systems::UserCommands"/>
    <plugin filename="gz-sim-scene-broadcaster-system" name="gz::sim::systems::SceneBroadcaster"/>
    <plugin filename="gz-sim-sensors-system" name="gz::sim::systems::Sensors">
      <render_engine>ogre2</render_engine>
    </plugin>

    <light type="directional" name="sun">
      <cast_shadows>true</cast_shadows>
      <pose>0 0 10 0 0 0</pose>
      <diffuse>0.8 0.8 0.8 1</diffuse>
      <specular>0.2 0.2 0.2 1</specular>
      <attenuation><range>1000</range><constant>0.9</constant><linear>0.01</linear><quadratic>0.001</quadratic></attenuation>
      <direction>-0.5 0.1 -0.9</direction>
    </light>

    <model name="ground"><static>true</static>
      <link name="link">
        <collision name="c"><geometry><plane><normal>0 0 1</normal><size>100 100</size></plane></geometry></collision>
        <visual name="v"><geometry><plane><normal>0 0 1</normal><size>100 100</size></plane></geometry>
          <material><ambient>0.6 0.6 0.6 1</ambient><diffuse>0.6 0.6 0.6 1</diffuse></material></visual>
      </link>
    </model>

    <!-- Shelves: 0.4(depth-x) x 1.5(wide-y) x 1.0(height-z), front faces -x toward robot -->
    <!-- SHELF 1 at y=0, items in front at x=2.6 -->
    <model name="shelf1_rack"><static>true</static><pose>3 0 0.5 0 0 0</pose>
      <link name="l"><visual name="v"><geometry><box><size>0.4 1.5 1.0</size></box></geometry>
        <material><ambient>0.45 0.35 0.2 1</ambient><diffuse>0.45 0.35 0.2 1</diffuse></material></visual>
        <collision name="c"><geometry><box><size>0.4 1.5 1.0</size></box></geometry></collision></link>
    </model>
    <model name="s1_item1"><static>true</static><pose>2.6 -0.4 0.65 0 0 0</pose>
      <link name="l"><visual name="v"><geometry><box><size>0.2 0.2 0.3</size></box></geometry>
        <material><ambient>0.8 0.1 0.1 1</ambient><diffuse>0.8 0.1 0.1 1</diffuse></material></visual></link>
    </model>
    <model name="s1_item2"><static>true</static><pose>2.6 0.0 0.65 0 0 0</pose>
      <link name="l"><visual name="v"><geometry><box><size>0.2 0.2 0.3</size></box></geometry>
        <material><ambient>0.1 0.7 0.1 1</ambient><diffuse>0.1 0.7 0.1 1</diffuse></material></visual></link>
    </model>
    <model name="s1_item3"><static>true</static><pose>2.6 0.4 0.65 0 0 0</pose>
      <link name="l"><visual name="v"><geometry><box><size>0.2 0.2 0.3</size></box></geometry>
        <material><ambient>0.1 0.1 0.8 1</ambient><diffuse>0.1 0.1 0.8 1</diffuse></material></visual></link>
    </model>

    <!-- SHELF 2 at y=3 (damaged: tilted item, dark stain, fallen box) -->
    <model name="shelf2_rack"><static>true</static><pose>3 3 0.5 0 0 0</pose>
      <link name="l"><visual name="v"><geometry><box><size>0.4 1.5 1.0</size></box></geometry>
        <material><ambient>0.4 0.3 0.15 1</ambient><diffuse>0.4 0.3 0.15 1</diffuse></material></visual>
        <collision name="c"><geometry><box><size>0.4 1.5 1.0</size></box></geometry></collision></link>
    </model>
    <model name="s2_tilted"><static>true</static><pose>2.6 2.6 0.65 0 0 0.4</pose>
      <link name="l"><visual name="v"><geometry><box><size>0.2 0.2 0.3</size></box></geometry>
        <material><ambient>0.6 0.1 0.1 1</ambient><diffuse>0.6 0.1 0.1 1</diffuse></material></visual></link>
    </model>
    <model name="s2_damaged"><static>true</static><pose>2.6 3.0 0.55 0.3 0 0</pose>
      <link name="l"><visual name="v"><geometry><box><size>0.2 0.2 0.3</size></box></geometry>
        <material><ambient>0.15 0.1 0.05 1</ambient><diffuse>0.15 0.1 0.05 1</diffuse></material></visual></link>
    </model>
    <model name="s2_fallen"><static>true</static><pose>2.3 3.3 0.1 1.57 0 0</pose>
      <link name="l"><visual name="v"><geometry><box><size>0.2 0.2 0.3</size></box></geometry>
        <material><ambient>0.7 0.4 0.0 1</ambient><diffuse>0.7 0.4 0.0 1</diffuse></material></visual></link>
    </model>

    <!-- SHELF 3 at y=6, normal items -->
    <model name="shelf3_rack"><static>true</static><pose>3 6 0.5 0 0 0</pose>
      <link name="l"><visual name="v"><geometry><box><size>0.4 1.5 1.0</size></box></geometry>
        <material><ambient>0.45 0.35 0.2 1</ambient><diffuse>0.45 0.35 0.2 1</diffuse></material></visual>
        <collision name="c"><geometry><box><size>0.4 1.5 1.0</size></box></geometry></collision></link>
    </model>
    <model name="s3_item1"><static>true</static><pose>2.6 5.6 0.65 0 0 0</pose>
      <link name="l"><visual name="v"><geometry><box><size>0.2 0.2 0.3</size></box></geometry>
        <material><ambient>0.8 0.8 0.0 1</ambient><diffuse>0.8 0.8 0.0 1</diffuse></material></visual></link>
    </model>
    <model name="s3_item2"><static>true</static><pose>2.6 6.0 0.65 0 0 0</pose>
      <link name="l"><visual name="v"><geometry><box><size>0.2 0.2 0.3</size></box></geometry>
        <material><ambient>0.0 0.6 0.6 1</ambient><diffuse>0.0 0.6 0.6 1</diffuse></material></visual></link>
    </model>
    <model name="s3_item3"><static>true</static><pose>2.6 6.4 0.65 0 0 0</pose>
      <link name="l"><visual name="v"><geometry><box><size>0.2 0.2 0.3</size></box></geometry>
        <material><ambient>0.6 0.0 0.6 1</ambient><diffuse>0.6 0.0 0.6 1</diffuse></material></visual></link>
    </model>

    <!-- ROBOT - camera raised to see shelf items -->
    <model name="robot">
      <pose>0 0 0.15 0 0 0</pose>
      <link name="chassis">
        <inertial><mass>5.0</mass><inertia><ixx>0.1</ixx><iyy>0.1</iyy><izz>0.05</izz></inertia></inertial>
        <visual name="v"><geometry><box><size>0.5 0.3 0.15</size></box></geometry>
          <material><ambient>0.1 0.1 0.8 1</ambient><diffuse>0.1 0.1 0.8 1</diffuse></material></visual>
        <collision name="c"><geometry><box><size>0.5 0.3 0.15</size></box></geometry></collision>
      </link>
      <link name="left_wheel">
        <pose>-0.15 0.19 -0.05 -1.5707 0 0</pose>
        <inertial><mass>1</mass><inertia><ixx>0.02</ixx><iyy>0.02</iyy><izz>0.02</izz></inertia></inertial>
        <visual name="v"><geometry><cylinder><radius>0.1</radius><length>0.05</length></cylinder></geometry>
          <material><ambient>0.2 0.2 0.2 1</ambient></material></visual>
        <collision name="c"><geometry><cylinder><radius>0.1</radius><length>0.05</length></cylinder></geometry></collision>
      </link>
      <link name="right_wheel">
        <pose>-0.15 -0.19 -0.05 -1.5707 0 0</pose>
        <inertial><mass>1</mass><inertia><ixx>0.02</ixx><iyy>0.02</iyy><izz>0.02</izz></inertia></inertial>
        <visual name="v"><geometry><cylinder><radius>0.1</radius><length>0.05</length></cylinder></geometry>
          <material><ambient>0.2 0.2 0.2 1</ambient></material></visual>
        <collision name="c"><geometry><cylinder><radius>0.1</radius><length>0.05</length></cylinder></geometry></collision>
      </link>
      <link name="caster">
        <pose>0.18 0 -0.12 0 0 0</pose>
        <inertial><mass>0.5</mass><inertia><ixx>0.005</ixx><iyy>0.005</iyy><izz>0.005</izz></inertia></inertial>
        <visual name="v"><geometry><sphere><radius>0.04</radius></sphere></geometry></visual>
        <collision name="c"><geometry><sphere><radius>0.04</radius></sphere></geometry>
          <surface><friction><ode><mu>0</mu><mu2>0</mu2></ode></friction></surface></collision>
      </link>
      <link name="camera_link">
        <pose>0.2 0 0.45 0 0.2 0</pose>
        <inertial><mass>0.1</mass><inertia><ixx>0.0001</ixx><iyy>0.0001</iyy><izz>0.0001</izz></inertia></inertial>
        <visual name="v"><geometry><box><size>0.05 0.05 0.05</size></box></geometry>
          <material><ambient>0.8 0.0 0.0 1</ambient><diffuse>0.8 0 0 1</diffuse></material></visual>
        <sensor name="camera" type="camera">
          <always_on>true</always_on><update_rate>10</update_rate><topic>/camera/image_raw</topic>
          <camera><horizontal_fov>1.2</horizontal_fov>
            <image><width>640</width><height>480</height></image>
            <clip><near>0.1</near><far>50</far></clip></camera>
        </sensor>
      </link>
      <joint name="left_wheel_joint" type="revolute">
        <parent>chassis</parent><child>left_wheel</child>
        <axis><xyz>0 0 1</xyz><limit><lower>-1.79769e+308</lower><upper>1.79769e+308</upper></limit></axis>
      </joint>
      <joint name="right_wheel_joint" type="revolute">
        <parent>chassis</parent><child>right_wheel</child>
        <axis><xyz>0 0 1</xyz><limit><lower>-1.79769e+308</lower><upper>1.79769e+308</upper></limit></axis>
      </joint>
      <joint name="caster_wheel" type="ball"><parent>chassis</parent><child>caster</child></joint>
      <joint name="camera_joint" type="fixed"><parent>chassis</parent><child>camera_link</child></joint>

      <plugin filename="gz-sim-diff-drive-system" name="gz::sim::systems::DiffDrive">
        <left_joint>left_wheel_joint</left_joint>
        <right_joint>right_wheel_joint</right_joint>
        <wheel_separation>0.38</wheel_separation>
        <wheel_radius>0.1</wheel_radius>
        <odom_publish_frequency>20</odom_publish_frequency>
        <topic>/cmd_vel</topic>
        <odom_topic>/odom</odom_topic>
        <tf_topic>/tf</tf_topic>
        <frame_id>odom</frame_id>
        <child_frame_id>chassis</child_frame_id>
        <max_linear_acceleration>1</max_linear_acceleration>
        <min_linear_acceleration>-1</min_linear_acceleration>
        <max_angular_acceleration>2</max_angular_acceleration>
        <min_angular_acceleration>-2</min_angular_acceleration>
        <max_linear_velocity>0.5</max_linear_velocity>
        <min_linear_velocity>-0.5</min_linear_velocity>
        <max_angular_velocity>1</max_angular_velocity>
        <min_angular_velocity>-1</min_angular_velocity>
      </plugin>
    </model>

  </world>
</sdf>
